2021-01-16 15:19:31,503 INFO    MainThread:2169830 [wandb_setup.py:_flush():70] setting env: {}
2021-01-16 15:19:31,503 INFO    MainThread:2169830 [wandb_setup.py:_flush():70] multiprocessing start_methods=fork,spawn,forkserver
2021-01-16 15:19:31,503 INFO    MainThread:2169830 [wandb_setup.py:_flush():70] setting login settings: {}
2021-01-16 15:19:31,503 INFO    MainThread:2169830 [wandb_init.py:_log_setup():318] Logging user logs to /home/whiteashes/Project/FedML/fedml_experiments/FedAvgExp/wandb/run-20210116_151931-1zmus15v/logs/debug.log
2021-01-16 15:19:31,503 INFO    MainThread:2169830 [wandb_init.py:_log_setup():319] Logging internal logs to /home/whiteashes/Project/FedML/fedml_experiments/FedAvgExp/wandb/run-20210116_151931-1zmus15v/logs/debug-internal.log
2021-01-16 15:19:32,292 WARNING MainThread:2169830 [wandb_init.py:init():638] interrupted
Traceback (most recent call last):
  File "/home/whiteashes/anaconda3/envs/fedml/lib/python3.7/site-packages/wandb/sdk/wandb_init.py", line 618, in init
    run = wi.init()
  File "/home/whiteashes/anaconda3/envs/fedml/lib/python3.7/site-packages/wandb/sdk/wandb_init.py", line 441, in init
    current_version=wandb.__version__
  File "/home/whiteashes/anaconda3/envs/fedml/lib/python3.7/site-packages/wandb/sdk/interface/interface.py", line 632, in communicate_check_version
    result = self._communicate(rec)
  File "/home/whiteashes/anaconda3/envs/fedml/lib/python3.7/site-packages/wandb/sdk/interface/interface.py", line 463, in _communicate
    f = future.get(timeout)
  File "/home/whiteashes/anaconda3/envs/fedml/lib/python3.7/site-packages/wandb/sdk/interface/interface.py", line 63, in get
    is_set = self._object_ready.wait(timeout)
  File "/home/whiteashes/anaconda3/envs/fedml/lib/python3.7/threading.py", line 552, in wait
    signaled = self._cond.wait(timeout)
  File "/home/whiteashes/anaconda3/envs/fedml/lib/python3.7/threading.py", line 300, in wait
    gotit = waiter.acquire(True, timeout)
KeyboardInterrupt
2021-01-16 15:19:32,294 INFO    MainThread:2169830 [internal.py:handle_exit():139] Internal process exited
